2025-09-18 22:25:24,469 - database - INFO - test_basic_logging:51 - Database connection established
2025-09-18 22:25:24,469 - database - INFO - test_basic_logging:52 - Query executed successfully
2025-09-18 22:25:24,476 - database - INFO - log_structured:121 - {"timestamp": "2025-09-18T22:25:24.476086", "level": "INFO", "message": "Database operation: INSERT", "operation": "INSERT", "table": "videos", "video_id": 1, "video_name": "test.mp4"}
2025-09-18 22:25:24,476 - database - INFO - log_structured:121 - {"timestamp": "2025-09-18T22:25:24.476261", "level": "INFO", "message": "Database operation: SELECT", "operation": "SELECT", "table": "persons", "query_filter": "video_id=1"}
2025-09-18 22:25:24,487 - database - ERROR - log_error_with_traceback:140 - Error occurred: {"error_type": "RuntimeError", "error_message": "Database connection failed", "traceback": "Traceback (most recent call last):\n  File \"D:\\videos analysis\\test_logging.py\", line 103, in test_error_logging\n    raise RuntimeError(\"Database connection failed\")\nRuntimeError: Database connection failed\n", "context": {"context": "database_test", "operation": "connect"}}
2025-09-18 22:27:05,355 - database - INFO - test_basic_logging:51 - Database connection established
2025-09-18 22:27:05,355 - database - INFO - test_basic_logging:52 - Query executed successfully
2025-09-18 22:27:05,357 - database - INFO - log_structured:121 - {"timestamp": "2025-09-18T22:27:05.357771", "level": "INFO", "message": "Database operation: INSERT", "operation": "INSERT", "table": "videos", "video_id": 1, "video_name": "test.mp4"}
2025-09-18 22:27:05,357 - database - INFO - log_structured:121 - {"timestamp": "2025-09-18T22:27:05.357868", "level": "INFO", "message": "Database operation: SELECT", "operation": "SELECT", "table": "persons", "query_filter": "video_id=1"}
2025-09-18 22:27:05,367 - database - ERROR - log_error_with_traceback:140 - Error occurred: {"error_type": "RuntimeError", "error_message": "Database connection failed", "traceback": "Traceback (most recent call last):\n  File \"D:\\videos analysis\\test_logging.py\", line 103, in test_error_logging\n    raise RuntimeError(\"Database connection failed\")\nRuntimeError: Database connection failed\n", "context": {"context": "database_test", "operation": "connect"}}
2025-09-18 22:29:50,487 - database - INFO - test_basic_logging:51 - Database connection established
2025-09-18 22:29:50,487 - database - INFO - test_basic_logging:52 - Query executed successfully
2025-09-18 22:29:50,490 - database - INFO - log_structured:121 - {"timestamp": "2025-09-18T22:29:50.490392", "level": "INFO", "message": "Database operation: INSERT", "operation": "INSERT", "table": "videos", "video_id": 1, "video_name": "test.mp4"}
2025-09-18 22:29:50,490 - database - INFO - log_structured:121 - {"timestamp": "2025-09-18T22:29:50.490648", "level": "INFO", "message": "Database operation: SELECT", "operation": "SELECT", "table": "persons", "query_filter": "video_id=1"}
2025-09-18 22:29:50,499 - database - ERROR - log_error_with_traceback:140 - Error occurred: {"error_type": "RuntimeError", "error_message": "Database connection failed", "traceback": "Traceback (most recent call last):\n  File \"D:\\videos analysis\\test_logging.py\", line 103, in test_error_logging\n    raise RuntimeError(\"Database connection failed\")\nRuntimeError: Database connection failed\n", "context": {"context": "database_test", "operation": "connect"}}
