2025-09-18 22:25:24,486 - errors - ERROR - log_error_with_traceback:144 - Error occurred: {"error_type": "ValueError", "error_message": "This is a test error for logging", "traceback": "Traceback (most recent call last):\n  File \"D:\\videos analysis\\test_logging.py\", line 97, in test_error_logging\n    raise ValueError(\"This is a test error for logging\")\nValueError: This is a test error for logging\n", "context": {"context": "test_error_logging", "test_id": 123}}
2025-09-18 22:25:24,487 - errors - ERROR - log_error_with_traceback:144 - Error occurred: {"error_type": "RuntimeError", "error_message": "Database connection failed", "traceback": "Traceback (most recent call last):\n  File \"D:\\videos analysis\\test_logging.py\", line 103, in test_error_logging\n    raise RuntimeError(\"Database connection failed\")\nRuntimeError: Database connection failed\n", "context": {"context": "database_test", "operation": "connect"}}
2025-09-18 22:27:05,366 - errors - ERROR - log_error_with_traceback:144 - Error occurred: {"error_type": "ValueError", "error_message": "This is a test error for logging", "traceback": "Traceback (most recent call last):\n  File \"D:\\videos analysis\\test_logging.py\", line 97, in test_error_logging\n    raise ValueError(\"This is a test error for logging\")\nValueError: This is a test error for logging\n", "context": {"context": "test_error_logging", "test_id": 123}}
2025-09-18 22:27:05,367 - errors - ERROR - log_error_with_traceback:144 - Error occurred: {"error_type": "RuntimeError", "error_message": "Database connection failed", "traceback": "Traceback (most recent call last):\n  File \"D:\\videos analysis\\test_logging.py\", line 103, in test_error_logging\n    raise RuntimeError(\"Database connection failed\")\nRuntimeError: Database connection failed\n", "context": {"context": "database_test", "operation": "connect"}}
2025-09-18 22:29:50,498 - errors - ERROR - log_error_with_traceback:144 - Error occurred: {"error_type": "ValueError", "error_message": "This is a test error for logging", "traceback": "Traceback (most recent call last):\n  File \"D:\\videos analysis\\test_logging.py\", line 97, in test_error_logging\n    raise ValueError(\"This is a test error for logging\")\nValueError: This is a test error for logging\n", "context": {"context": "test_error_logging", "test_id": 123}}
2025-09-18 22:29:50,499 - errors - ERROR - log_error_with_traceback:144 - Error occurred: {"error_type": "RuntimeError", "error_message": "Database connection failed", "traceback": "Traceback (most recent call last):\n  File \"D:\\videos analysis\\test_logging.py\", line 103, in test_error_logging\n    raise RuntimeError(\"Database connection failed\")\nRuntimeError: Database connection failed\n", "context": {"context": "database_test", "operation": "connect"}}
